08.08.18 18:26:30: ERROR: logger_1: line 6: debug
08.08.18 18:26:54: ERROR: logger_1: line 55: debug
08.08.18 18:27:09: ERROR: logger_1: line 6: debug
08.08.18 18:29:55: ERROR: logger_1: line 9: exception
Traceback (most recent call last):
  File "c:\Users\Huy\Documents\GitHub\huys_python\tests\parallel\parallel_logging.py", line 7, in <module>
    2/0
ZeroDivisionError: division by zero
08.08.18 18:30:04: ERROR: logger_1: line 55: exception
NoneType: None
08.08.18 18:30:50: ERROR: logger_1: line 55: division by zero
NoneType: None
08.08.18 18:34:31: ERROR: logger_1: line 9: division by zero
Traceback (most recent call last):
  File "c:\Users\Huy\Documents\GitHub\huys_python\tests\parallel\parallel_logging.py", line 7, in <module>
    2/0
ZeroDivisionError: division by zero
08.08.18 18:35:23: ERROR: logger_1: line 9: division by zero
08.08.18 18:35:29: ERROR: logger_1: line 55: division by zero
08.08.18 18:36:54: ERROR: logger_1: line 55: division by zero
08.08.18 18:43:13: ERROR: logger_1: line 9: division by zero
Traceback (most recent call last):
  File "c:\Users\Huy\Documents\GitHub\huys_python\tests\parallel\parallel_logging.py", line 7, in <module>
    2/0
ZeroDivisionError: division by zero
08.08.18 18:43:56: ERROR: logger_1: line 9: division by zero
Traceback (most recent call last):
  File "c:\Users\Huy\Documents\GitHub\huys_python\tests\parallel\parallel_logging.py", line 7, in <module>
    2/0
ZeroDivisionError: division by zero
08.08.18 18:47:50: ERROR: logger_1: line 55: division by zero
NoneType: None
08.08.18 19:02:15: ERROR: logger_1: line 55: division by zero
NoneType: None
08.08.18 19:04:00: ERROR: logger_1: line 55: (ZeroDivisionError('division by zero',), True)
08.08.18 19:04:14: ERROR: logger_1: line 55: (ZeroDivisionError('division by zero',), True)
08.08.18 19:07:03: ERROR: logger_1: line 55: <traceback object at 0x0000021D2F14D408>
NoneType: None
08.08.18 19:07:42: ERROR: logger_1: line 55: division by zero
NoneType: None
08.08.18 19:13:51: ERROR: logger_1: line 55: division by zero
NoneType: None
08.08.18 19:14:18: ERROR: logger_1: line 55: <traceback object at 0x00000239F92A02C8>
NoneType: None
08.08.18 19:18:19: ERROR: logger_1: line 55: division by zero
NoneType: None
08.08.18 19:18:26: ERROR: logger_1: line 55: division by zero
NoneType: None
08.08.18 19:19:14: ERROR: logger_1: line 55: division by zero
NoneType: None
08.08.18 19:19:34: ERROR: logger_1: line 55: division by zero
NoneType: None
08.08.18 19:20:43: ERROR: logger_1: line 55: division by zero
NoneType: None
08.08.18 19:21:04: ERROR: logger_1: line 55: division by zero
NoneType: None
08.08.18 19:21:55: ERROR: logger_1: line 55: [<FrameSummary file c:\Users\Huy\Documents\GitHub\huys_python\tests\parallel\parallel_logging.py, line 8 in <module>>]
NoneType: None
08.08.18 19:22:17: ERROR: logger_1: line 55: None
NoneType: None
08.08.18 19:31:12: ERROR: logger_1: line 55: division by zero
NoneType: None
08.08.18 19:32:21: ERROR: logger_1: line 55: (ZeroDivisionError('division by zero',), (<class 'ZeroDivisionError'>, ZeroDivisionError('division by zero',), <traceback object at 0x0000021F2BDF01C8>))
NoneType: None
08.08.18 19:33:04: ERROR: logger_1: line 55: (ZeroDivisionError('division by zero',), (<class 'ZeroDivisionError'>, ZeroDivisionError('division by zero',), <traceback object at 0x0000026A017F01C8>))
08.08.18 19:36:21: ERROR: logger_1: line 122: division by zero
Traceback (most recent call last):
  File "c:\Users\Huy\Documents\GitHub\huys_python\tests\parallel\parallel_logging.py", line 8, in <module>
    2/0
ZeroDivisionError: division by zero
08.08.18 19:36:51: ERROR: logger_1: line 122: division by zero
Traceback (most recent call last):
  File "c:\Users\Huy\Documents\GitHub\huys_python\tests\parallel\parallel_logging.py", line 8, in <module>
    2/0
ZeroDivisionError: division by zero
08.08.18 19:37:09: ERROR: logger_1: line 55: (ZeroDivisionError('division by zero',), (<class 'ZeroDivisionError'>, ZeroDivisionError('division by zero',), <traceback object at 0x0000024EAFB10208>))
08.08.18 19:37:53: ERROR: logger_1: line 55: division by zero
Traceback (most recent call last):
  File "c:\Users\Huy\Documents\GitHub\huys_python\tests\parallel\parallel_logging.py", line 8, in <module>
    2/0
ZeroDivisionError: division by zero
08.08.18 19:37:53: ERROR: logger_1: line 122: division by zero
Traceback (most recent call last):
  File "c:\Users\Huy\Documents\GitHub\huys_python\tests\parallel\parallel_logging.py", line 8, in <module>
    2/0
ZeroDivisionError: division by zero
08.08.18 19:37:58: ERROR: logger_1: line 55: division by zero
Traceback (most recent call last):
  File "c:\Users\Huy\Documents\GitHub\huys_python\tests\parallel\parallel_logging.py", line 8, in <module>
    2/0
ZeroDivisionError: division by zero
08.08.18 19:38:10: ERROR: logger_1: line 55: division by zero
Traceback (most recent call last):
  File "c:\Users\Huy\Documents\GitHub\huys_python\tests\parallel\parallel_logging.py", line 8, in <module>
    2/0
ZeroDivisionError: division by zero
08.08.18 19:38:57: ERROR: logger_1: line 55: division by zero
Traceback (most recent call last):
  File "c:\Users\Huy\Documents\GitHub\huys_python\tests\parallel\parallel_logging.py", line 8, in <module>
    2/0
ZeroDivisionError: division by zero
08.08.18 19:39:07: ERROR: logger_1: line 55: division by zero
Traceback (most recent call last):
  File "c:\Users\Huy\Documents\GitHub\huys_python\tests\parallel\parallel_logging.py", line 8, in <module>
    2/0
ZeroDivisionError: division by zero
08.08.18 19:39:32: ERROR: logger_1: line 55: division by zero
Traceback (most recent call last):
  File "c:\Users\Huy\Documents\GitHub\huys_python\tests\parallel\parallel_logging.py", line 8, in <module>
    2/0
ZeroDivisionError: division by zero
08.08.18 19:39:39: ERROR: logger_1: line 11: division by zero
Traceback (most recent call last):
  File "c:\Users\Huy\Documents\GitHub\huys_python\tests\parallel\parallel_logging.py", line 8, in <module>
    2/0
ZeroDivisionError: division by zero
08.08.18 19:41:43: ERROR: logger_1: line 11: division by zero
Traceback (most recent call last):
  File "c:\Users\Huy\Documents\GitHub\huys_python\tests\parallel\parallel_logging.py", line 8, in <module>
    2/0
ZeroDivisionError: division by zero
08.08.18 19:41:45: ERROR: logger_1: line 17: list index out of range
Traceback (most recent call last):
  File "c:\Users\Huy\Documents\GitHub\huys_python\tests\parallel\parallel_logging.py", line 15, in <module>
    print(array[2])
IndexError: list index out of range
08.08.18 19:41:57: ERROR: logger_1: line 55: division by zero
Traceback (most recent call last):
  File "c:\Users\Huy\Documents\GitHub\huys_python\tests\parallel\parallel_logging.py", line 8, in <module>
    2/0
ZeroDivisionError: division by zero
08.08.18 19:41:57: ERROR: logger_1: line 55: list index out of range
Traceback (most recent call last):
  File "c:\Users\Huy\Documents\GitHub\huys_python\tests\parallel\parallel_logging.py", line 15, in <module>
    print(array[2])
IndexError: list index out of range
